<?xml version="1.0"?>
<sdf version="1.4">
    <model name="simple_gripper">
        <link name="riser">
            <pose>-0.025 0.0 0.125 0 0 0</pose>
            <inertial>
                <pose>0 0 0 0 0 0</pose>
                <inertia>
                    <ixx>0.01</ixx>
                    <ixy>0</ixy>
                    <ixz>0</ixz>
                    <iyy>0.01</iyy>
                    <iyz>0</iyz>
                    <izz>0.01</izz>
                </inertia>
                <mass>10.0</mass>
            </inertial>
            <collision name="collision">
                <geometry>
                    <box>
                        <size>0.025 0.025 0.25</size>
                    </box>
                </geometry>
            </collision>
            <visual name="visual">
                <geometry>
                    <box>
                        <size>0.025 0.025 0.25</size>
                    </box>
                </geometry>
                <material>
                    <script>Gazebo/Purple</script>
                </material>
            </visual>
        </link>
        <link name="palm">
            <pose>0.0 0.0 0.0125 0 0 0</pose>
            <inertial>
                <inertia>
                    <ixx>0.01</ixx>
                    <ixy>0</ixy>
                    <ixz>0</ixz>
                    <iyy>0.01</iyy>
                    <iyz>0</iyz>
                    <izz>0.01</izz>
                </inertia>
                <mass>0.5</mass>
            </inertial>
            <collision name="collision">
                <geometry>
                    <box>
                        <size>0.025 0.05 0.025</size>
                    </box>
                </geometry>
            </collision>
            <visual name="visual">
                <geometry>
                    <box>
                        <size>0.025 0.05 0.025</size>
                    </box>
                </geometry>
                <material>
                    <script>Gazebo/Red</script>
                </material>
            </visual>
        </link>
        <link name="left_finger">
            <pose>0.0265 0.039 0.0125 0 0 -0.78539</pose>
            <inertial>
                <inertia>
                    <ixx>0.01</ixx>
                    <ixy>0</ixy>
                    <ixz>0</ixz>
                    <iyy>0.01</iyy>
                    <iyz>0</iyz>
                    <izz>0.01</izz>
                </inertia>
                <mass>0.1</mass>
            </inertial>
            <collision name="collision">
                <geometry>
                    <box>
                        <size>0.025 0.075 0.025</size>
                    </box>
                </geometry>
            </collision>
            <visual name="visual">
                <geometry>
                    <box>
                        <size>0.025 0.075 0.025</size>
                    </box>
                </geometry>
                <material>
                    <script>Gazebo/Blue</script>
                </material>
            </visual>
        </link>
        <link name="left_finger_tip">
            <pose>0.078 0.053 0.0125 0 0 1.5707</pose>
            <inertial>
                <inertia>
                    <ixx>0.01</ixx>
                    <ixy>0</ixy>
                    <ixz>0</ixz>
                    <iyy>0.01</iyy>
                    <iyz>0</iyz>
                    <izz>0.01</izz>
                </inertia>
                <mass>0.1</mass>
            </inertial>
            <collision name="collision">
                <geometry>
                    <box>
                        <size>0.025 0.05 0.025</size>
                    </box>
                </geometry>
            </collision>
            <visual name="visual">
                <geometry>
                    <box>
                        <size>0.025 0.05 0.025</size>
                    </box>
                </geometry>
                <material>
                    <script>Gazebo/Blue</script>
                </material>
            </visual>
        </link>
        <link name="right_finger">
            <pose>0.0265 -0.039 0.0125 0 0 0.78539</pose>
            <inertial>
                <inertia>
                    <ixx>0.01</ixx>
                    <ixy>0</ixy>
                    <ixz>0</ixz>
                    <iyy>0.01</iyy>
                    <iyz>0</iyz>
                    <izz>0.01</izz>
                </inertia>
                <mass>0.1</mass>
            </inertial>
            <collision name="collision">
                <geometry>
                    <box>
                        <size>0.025 0.075 0.025</size>
                    </box>
                </geometry>
            </collision>
            <visual name="visual">
                <geometry>
                    <box>
                        <size>0.025 0.075 0.025</size>
                    </box>
                </geometry>
                <material>
                    <script>Gazebo/Green</script>
                </material>
            </visual>
        </link>
        <link name="right_finger_tip">
            <pose>0.078 -0.053 0.0125 0 0 1.5707</pose>
            <inertial>
                <inertia>
                    <ixx>0.01</ixx>
                    <ixy>0</ixy>
                    <ixz>0</ixz>
                    <iyy>0.01</iyy>
                    <iyz>0</iyz>
                    <izz>0.01</izz>
                </inertia>
                <mass>0.1</mass>
            </inertial>
            <collision name="collision">
                <geometry>
                    <box>
                        <size>0.025 0.05 0.025</size>
                    </box>
                </geometry>
            </collision>
            <visual name="visual">
                <geometry>
                    <box>
                        <size>0.025 0.05 0.025</size>
                    </box>
                </geometry>
                <material>
                    <script>Gazebo/Green</script>
                </material>
            </visual>
        </link>
        <static>false</static>
    <joint name="palm_left_finger" type="revolute">
            <pose>0 -0.025 0 0 0 0</pose>
            <child>left_finger</child>
            <parent>palm</parent>
            <axis>
                <limit>
                    <lower>-0.4</lower>
                    <upper>0.4</upper>
                </limit>
                <xyz>0 0 1</xyz>
            </axis>
        </joint>
        <joint name="left_finger_tip" type="revolute">
            <pose>0 0.025 0 0 0 0</pose>
            <child>left_finger_tip</child>
            <parent>left_finger</parent>
            <axis>
                <limit>
                    <lower>-0.4</lower>
                    <upper>0.4</upper>
                </limit>
                <xyz>0 0 1</xyz>
            </axis>
        </joint>
        <joint name="palm_right_finger" type="revolute">
            <pose>0 0.025 0 0 0 0</pose>
            <child>right_finger</child>
            <parent>palm</parent>
            <axis>
                <limit>
                    <lower>-0.4</lower>
                    <upper>0.4</upper>
                </limit>
                <xyz>0 0 1</xyz>
            </axis>
        </joint>
        <joint name="right_finger_tip" type="revolute">
            <pose>0 0.025 0 0 0 0</pose>
            <child>right_finger_tip</child>
            <parent>right_finger</parent>
            <axis>
                <limit>
                    <lower>-0.4</lower>
                    <upper>0.4</upper>
                </limit>
                <xyz>0 0 1</xyz>
            </axis>
        </joint>
        <joint name="palm_riser" type="prismatic">
            <child>palm</child>
            <parent>riser</parent>
            <axis>
                <limit>
                    <lower>0</lower>
                    <upper>0.9</upper>
                </limit>
                <xyz>0 0 1</xyz>
            </axis>
        </joint>
    </model>
</sdf>

